<?xml version="1.0"?>
<robot name="robotica" xmlns:xacro="http://www.ros.org/wiki/xacro">

  <!-- ── Propiedades del robot ── -->
  <xacro:property name="wheel_radius"    value="0.033"/>  <!-- metros -->
  <xacro:property name="wheel_width"     value="0.020"/>
  <xacro:property name="base_length"     value="0.200"/>
  <xacro:property name="base_width"      value="0.150"/>
  <xacro:property name="base_height"     value="0.050"/>

  <!-- ── Base ── -->
  <link name="base_footprint"/>

  <joint name="base_joint" type="fixed">
    <parent link="base_footprint"/>
    <child link="base_link"/>
    <origin xyz="0 0 ${wheel_radius}" rpy="0 0 0"/>
  </joint>

  <link name="base_link">
    <visual>
      <geometry>
        <box size="${base_length} ${base_width} ${base_height}"/>
      </geometry>
      <material name="blue">
        <color rgba="0.2 0.4 0.8 1.0"/>
      </material>
    </visual>
    <collision>
      <geometry>
        <box size="${base_length} ${base_width} ${base_height}"/>
      </geometry>
    </collision>
    <inertial>
      <mass value="1.0"/>
      <inertia ixx="0.004" ixy="0" ixz="0" iyy="0.006" iyz="0" izz="0.009"/>
    </inertial>
  </link>

  <!-- ── IMU (posición central) ── -->
  <joint name="imu_joint" type="fixed">
    <parent link="base_link"/>
    <child link="imu_link"/>
    <origin xyz="0 0 0.025" rpy="0 0 0"/>
  </joint>
  <link name="imu_link"/>

  <!-- ── LIDAR (posición frontal) ── -->
  <joint name="lidar_joint" type="fixed">
    <parent link="base_link"/>
    <child link="lidar_link"/>
    <origin xyz="0.08 0 0.04" rpy="0 0 0"/>
  </joint>
  <link name="lidar_link"/>

  <!-- ── Gimbal/Cámara (servo x2) ── -->
  <joint name="gimbal_pan_joint" type="revolute">
    <parent link="base_link"/>
    <child link="gimbal_pan_link"/>
    <origin xyz="0.05 0 0.08" rpy="0 0 0"/>
    <axis xyz="0 0 1"/>
    <limit lower="-1.57" upper="1.57" effort="10" velocity="3.14"/>
  </joint>
  <link name="gimbal_pan_link"/>

  <joint name="gimbal_tilt_joint" type="revolute">
    <parent link="gimbal_pan_link"/>
    <child link="gimbal_tilt_link"/>
    <origin xyz="0 0 0.02" rpy="0 0 0"/>
    <axis xyz="0 1 0"/>
    <limit lower="-0.785" upper="0.785" effort="10" velocity="3.14"/>
  </joint>
  <link name="gimbal_tilt_link"/>

  <!-- ── Cámara HuskyLens en el gimbal ── -->
  <joint name="camera_joint" type="fixed">
    <parent link="gimbal_tilt_link"/>
    <child link="camera_link"/>
    <origin xyz="0.02 0 0" rpy="0 0 0"/>
  </joint>
  <link name="camera_link"/>

</robot>
